Workbook

Sheet seasons
A1: seasonId | B1: seasonName | C1: year | D1: isActive
A2: 2026 | B2: 2026 Season | C2: 2026 | D2: TRUE
A3: 2025 | B3: 2025 Season | C3: 2025 | D3: FALSE

Sheet teams
A1: teamId | B1: teamName | C1: primaryColor | D1: secondaryColor
A2: ball-starz | B2: Ball Starz | C2: #000000 | D2: #FFFFFF
A3: lmba-jam | B3: LMBA Jam | C3: #7DD3FC | D3: #0F172A
A4: thrillers | B4: Thrillers | C4: #2563EB | D4: #FFFFFF
A5: trust-the-process | B5: Trust The Process | C5: #FACC15 | D5: #111827
A6: department-of-offense | B6: Department of Offense | C6: #16A34A | D6: #FFFFFF
A7: prestige-worldwide | B7: Prestige Worldwide | C7: #7F1D1D | D7: #F8FAFC
A8: hash-slinging-slashers | B8: Hash-Slinging Slashers | C8: #EA580C | D8: #111827
A9: free-agent-team | B9: Free Agent Team | C9: #DC2626 | D9: #FFFFFF

Sheet seasonTeams
A1: seasonId | B1: teamId | C1: seasonTeamId | D1: captainPlayerId | E1: manualStandingRank
A2: 2026 | B2: ball-starz | C2: =A2&"-"&B2 -> 2026-ball-starz | D2: ryan-fontanazza
A3: 2026 | B3: lmba-jam | C3: =A3&"-"&B3 -> 2026-lmba-jam | D3: chris-clemente
A4: 2026 | B4: thrillers | C4: =A4&"-"&B4 -> 2026-thrillers | D4: connor-stine
A5: 2026 | B5: trust-the-process | C5: =A5&"-"&B5 -> 2026-trust-the-process | D5: kyle-ginter
A6: 2026 | B6: department-of-offense | C6: =A6&"-"&B6 -> 2026-department-of-offense | D6: eli-ratliff
A7: 2026 | B7: prestige-worldwide | C7: =A7&"-"&B7 -> 2026-prestige-worldwide | D7: david-hays
A8: 2026 | B8: hash-slinging-slashers | C8: =A8&"-"&B8 -> 2026-hash-slinging-slashers | D8: connor-thomas
A9: 2026 | B9: free-agent-team | C9: =A9&"-"&B9 -> 2026-free-agent-team | D9: jordan-williams

Sheet players
A1: playerId | B1: firstName | C1: lastName | D1: displayName
A2: =LOWER(SUBSTITUTE(B2&"-"&C2," ","-")) -> ryan-fontanazza | B2: Ryan | C2: Fontanazza | D2: =B2&" "&C2 -> Ryan Fontanazza
A3: =LOWER(SUBSTITUTE(B3&"-"&C3," ","-")) -> ryan-ricciardelli | B3: Ryan | C3: Ricciardelli | D3: =B3&" "&C3 -> Ryan Ricciardelli
A4: =LOWER(SUBSTITUTE(B4&"-"&C4," ","-")) -> sean-denson | B4: Sean | C4: Denson | D4: =B4&" "&C4 -> Sean Denson
A5: =LOWER(SUBSTITUTE(B5&"-"&C5," ","-")) -> guy-johnson | B5: Guy | C5: Johnson | D5: =B5&" "&C5 -> Guy Johnson
A6: =LOWER(SUBSTITUTE(B6&"-"&C6," ","-")) -> ryan-maloney | B6: Ryan | C6: Maloney | D6: =B6&" "&C6 -> Ryan Maloney
A7: =LOWER(SUBSTITUTE(B7&"-"&C7," ","-")) -> ryan-chapman | B7: Ryan | C7: Chapman | D7: =B7&" "&C7 -> Ryan Chapman
A8: =LOWER(SUBSTITUTE(B8&"-"&C8," ","-")) -> dom-sepko | B8: Dom | C8: Sepko | D8: =B8&" "&C8 -> Dom Sepko
A9: =LOWER(SUBSTITUTE(B9&"-"&C9," ","-")) -> matt-morini | B9: Matt | C9: Morini | D9: =B9&" "&C9 -> Matt Morini
A10: =LOWER(SUBSTITUTE(B10&"-"&C10," ","-")) -> clayton-kunzweiler | B10: Clayton | C10: Kunzweiler | D10: =B10&" "&C10 -> Clayton Kunzweiler
A11: =LOWER(SUBSTITUTE(B11&"-"&C11," ","-")) -> mj-pierre | B11: MJ | C11: Pierre | D11: =B11&" "&C11 -> MJ Pierre
A12: =LOWER(SUBSTITUTE(B12&"-"&C12," ","-")) -> chris-clemente | B12: Chris | C12: Clemente | D12: =B12&" "&C12 -> Chris Clemente
A13: =LOWER(SUBSTITUTE(B13&"-"&C13," ","-")) -> mike-ziller | B13: Mike | C13: Ziller | D13: =B13&" "&C13 -> Mike Ziller
... A84: =LOWER(SUBSTITUTE(B84&"-"&C84," ","-")) -> jossell-de-coteau | B84: Jossell | C84: De Coteau | D84: =B84&" "&C84 -> Jossell De Coteau

Sheet rosterSpots
A1: seasonId | B1: seasonTeamId | C1: teamId | D1: playerId | E1: jerseyNumber
A2: 2026 | B2: 2026-ball-starz | C2: ball-starz | D2: ryan-fontanazza | E2: 22
A3: 2026 | B3: 2026-ball-starz | C3: ball-starz | D3: ryan-ricciardelli | E3: 2
A4: 2026 | B4: 2026-ball-starz | C4: ball-starz | D4: sean-denson | E4: 33
A5: 2026 | B5: 2026-ball-starz | C5: ball-starz | D5: guy-johnson | E5: 9
A6: 2026 | B6: 2026-ball-starz | C6: ball-starz | D6: ryan-maloney | E6: 5
A7: 2026 | B7: 2026-ball-starz | C7: ball-starz | D7: ryan-chapman | E7: 20
A8: 2026 | B8: 2026-ball-starz | C8: ball-starz | D8: dom-sepko | E8: 3
A9: 2026 | B9: 2026-ball-starz | C9: ball-starz | D9: matt-morini | E9: 11
A10: 2026 | B10: 2026-ball-starz | C10: ball-starz | D10: clayton-kunzweiler | E10: 13
A11: 2026 | B11: 2026-ball-starz | C11: ball-starz | D11: mj-pierre | E11: 24
A12: 2026 | B12: 2026-lmba-jam | C12: lmba-jam | D12: chris-clemente | E12: 21
A13: 2026 | B13: 2026-lmba-jam | C13: lmba-jam | D13: mike-ziller | E13: 2
... A38: 2026 | B38: 2026-department-of-offense | C38: department-of-offense | D38: chris-ellis | E38: 0
A39: 2026 | B39: 2026-department-of-offense | C39: department-of-offense | D39: jason-kenny
A40: 2026 | B40: 2026-department-of-offense | C40: department-of-offense | D40: kyle-kelly | E40: 13
A41: 2026 | B41: 2026-department-of-offense | C41: department-of-offense | D41: sean-lane | E41: 3
A42: 2026 | B42: 2026-department-of-offense | C42: department-of-offense | D42: chris-kennedy | E42: 33
A43: 2026 | B43: 2026-department-of-offense | C43: department-of-offense | D43: anthony-marone | E43: 32
A44: 2026 | B44: 2026-thrillers | C44: thrillers | D44: doug-adams | E44: 3
A45: 2026 | B45: 2026-thrillers | C45: thrillers | D45: kelechi-madu | E45: 13
A46: 2026 | B46: 2026-thrillers | C46: thrillers | D46: connor-stine | E46: 14
A47: 2026 | B47: 2026-thrillers | C47: thrillers | D47: sragvi-tirumala | E47: 17
A48: 2026 | B48: 2026-thrillers | C48: thrillers | D48: janos-vajda | E48: 5
A49: 2026 | B49: 2026-thrillers | C49: thrillers | D49: brett-ziller | E49: 8
A50: 2026 | B50: 2026-thrillers | C50: thrillers | D50: allen-harley | E50: 21
A51: 2026 | B51: 2026-thrillers | C51: thrillers | D51: manthan-tailor | E51: 2
... A84: 2026 | B84: 2026-free-agent-team | C84: free-agent-team | D84: jossell-de-coteau | E84: 28

Sheet games
A1: gameId | B1: seasonId | C1: gameType | D1: week | E1: date | F1: time | G1: location | H1: homeTeamId | I1: awayTeamId | J1: firstHalfHomeScore | K1: firstHalfAwayScore | L1: secondHalfHomeScore | M1: secondHalfAwayScore | N1: homeScore | O1: awayScore | P1: overtimePeriods | Q1: status | R1: resultType | S1: headline | T1: recapTeaser
A2: =B2&"-w"&D2&"-g"&TEXT(COUNTIFS($B$2:B2,B2,$D$2:D2,D2),"00") -> 2026-w1-g01 | B2: 2026 | C2: regularSeason | D2: 1 | E2: 46112 | F2: 0.77083333 | G2: Moorestown Upper Elementary | H2: ball-starz | I2: lmba-jam | J2: 33 | K2: 19 | L2: 28 | M2: 30 | N2: 61 | O2: 49 | P2: 0 | Q2: final | R2: normal | S2: Ball Starz Get Revenge In Championship Rematch Behind Guy Johnson’s 23 | T2: Opening Night delivered an instant playoff-caliber showdown as Ball Starz knocked off defending champion LMBA Jam in a rematch of last season’s title game. Reigning MVP Guy Johnson led the charge with 23 points to help Ball Starz start 2026 with an early statement win.
A3: =B3&"-w"&D3&"-g"&TEXT(COUNTIFS($B$2:B3,B3,$D$2:D3,D3),"00") -> 2026-w1-g02 | B3: 2026 | C3: regularSeason | D3: 1 | E3: 46112 | F3: 0.8125 | G3: Moorestown Upper Elementary | H3: department-of-offense | I3: thrillers | J3: 34 | K3: 24 | L3: 20 | M3: 32 | N3: 54 | O3: 56 | P3: 0 | Q3: final | R3: normal | S3: Thrillers Storm Back From 10 Down Behind Adams And Ziller | T3: Thrillers erased a double-digit halftime deficit to steal a gritty 56-53 Opening Night win over Department of Offense. Doug Adams poured in 23 points while Brett Ziller added 12 as Thrillers closed the game with a dominant second-half rally.
A4: =B4&"-w"&D4&"-g"&TEXT(COUNTIFS($B$2:B4,B4,$D$2:D4,D4),"00") -> 2026-w2-g01 | B4: 2026 | C4: regularSeason | D4: 2 | E4: 46125 | F4: 0.77083333 | G4: Moorestown Upper Elementary | H4: prestige-worldwide | I4: hash-slinging-slashers | J4: 18 | K4: 30 | L4: 15 | M4: 18 | N4: 33 | O4: 48 | P4: 0 | Q4: final | R4: normal | S4: Hash-Slinging Slashers Clamp Down Early To Cruise Past Prestige Worldwide | T4: Hash-Slinging Slashers controlled the game from the opening tip, building a 12-point halftime lead before finishing off a comfortable 48-33 win over Prestige Worldwide. Strong defense and balanced scoring helped the Slashers improve to 1-0 on the young season.
A5: =B5&"-w"&D5&"-g"&TEXT(COUNTIFS($B$2:B5,B5,$D$2:D5,D5),"00") -> 2026-w2-g02 | B5: 2026 | C5: regularSeason | D5: 2 | E5: 46125 | F5: 0.8125 | G5: Moorestown Upper Elementary | H5: free-agent-team | I5: thrillers | N5: 41 | O5: 38 | P5: 0 | Q5: final | R5: normal | S5: Nkenna Drains Buzzer-Beating Step-Back Three To Lift Free Agent Team Over Thrillers | T5: Free-Agent Team pulled off a thrilling 41-38 victory over Thrillers thanks to a clutch buzzer-beater from sharpshooter Nkenna. With the game tied and the clock winding down, Nkenna stepped back beyond the arc and drained a deep three-pointer as time expired to secure the win for Free Agents in a game that had been neck-and-neck throughout. The victory marks a strong start for Free-Agent Team, while Thrillers will look to bounce back in their next outing.
A6: =B6&"-w"&D6&"-g"&TEXT(COUNTIFS($B$2:B6,B6,$D$2:D6,D6),"00") -> 2026-w2-g03 | B6: 2026 | C6: regularSeason | D6: 2 | E6: 46125 | F6: 0.85416667 | G6: Moorestown Upper Elementary | H6: department-of-offense | I6: ball-starz | J6: 19 | K6: 24 | L6: 25 | M6: 30 | N6: 44 | O6: 54 | P6: 0 | Q6: final | R6: normal | S6: Ball Starz Stay Unbeaten Behind Guy Johnson’s Five Threes | T6: Ball Starz used a balanced offensive attack and another explosive outing from Guy Johnson to defeat Department of Offense 54-44. Johnson knocked down five triples and scored 19 points as Ball Starz controlled the game from start to finish.
A7: =B7&"-w"&D7&"-g"&TEXT(COUNTIFS($B$2:B7,B7,$D$2:D7,D7),"00") -> 2026-w2-g04 | B7: 2026 | C7: regularSeason | D7: 2 | E7: 46126 | F7: 0.8125 | G7: Moorestown Upper Elementary | H7: trust-the-process | I7: prestige-worldwide | N7: 52 | O7: 40 | P7: 0 | Q7: final | R7: normal | S7: Trust The Process Pull Away Late To Secure First Win Of Season | T7: Trust The Process turned a competitive matchup into a comfortable double-digit victory in the second half, defeating Prestige Worldwide 52-40. A strong defensive effort helped TTP lock down the game late and even their record.
A8: =B8&"-w"&D8&"-g"&TEXT(COUNTIFS($B$2:B8,B8,$D$2:D8,D8),"00") -> 2026-w2-g05 | B8: 2026 | C8: regularSeason | D8: 2 | E8: 46126 | F8: 0.85416667 | G8: Moorestown Upper Elementary | H8: lmba-jam | I8: free-agent-team | N8: 70 | O8: 39 | P8: 0 | Q8: final | R8: normal | S8: LMBA Jam Explodes For 70 In Statement Win Over Free Agent Team | T8: LMBA Jam delivered one of the league’s most dominant offensive performances of the season, rolling past the Free Agent Team 70-39. LMBA Jam’s relentless pace and transition offense overwhelmed the Free Agents from the opening minutes.
A9: =B9&"-w"&D9&"-g"&TEXT(COUNTIFS($B$2:B9,B9,$D$2:D9,D9),"00") -> 2026-w2-g06 | B9: 2026 | C9: regularSeason | D9: 2 | E9: 46128 | F9: 0.77083333 | G9: Moorestown Upper Elementary | H9: hash-slinging-slashers | I9: lmba-jam | J9: 20 | K9: 20 | L9: 29 | M9: 12 | N9: 49 | O9: 32 | P9: 0 | Q9: final | R9: normal | S9: Hash-Slinging Slashers Dominate Second Half To Upset Short-Handed LMBA Jam | T9: After entering halftime tied at 20, Hash-Slinging Slashers completely took over in the second half to defeat a severely depleted LMBA Jam squad 49-32. LMBA Jam was limited to just five available players and missing key contributors Shelepets, Homsher, Brusseler, and Ziller, as the Slashers outscored them 29-12 after the break in one of the league’s strongest defensive performances of the season.
A10: =B10&"-w"&D10&"-g"&TEXT(COUNTIFS($B$2:B10,B10,$D$2:D10,D10),"00") -> 2026-w2-g07 | B10: 2026 | C10: regularSeason | D10: 2 | E10: 46128 | F10: 0.8125 | G10: Moorestown Upper Elementary | H10: ball-starz | I10: thrillers | J10: 26 | K10: 19 | L10: 19 | M10: 34 | N10: 45 | O10: 53 | P10: 0 | Q10: final | R10: normal | S10: Thrillers Rally Again, Erase Seven-Point Halftime Deficit Against Ball Starz | T10: For the second time in two weeks, Thrillers stormed back in the second half to steal a win, defeating Ball Starz 53-45. After trailing by seven at halftime, Thrillers exploded for 34 second-half points behind Doug Adams, who poured in 20 points overall with 12 coming after the break to fuel another comeback victory.
A11: =B11&"-w"&D11&"-g"&TEXT(COUNTIFS($B$2:B11,B11,$D$2:D11,D11),"00") -> 2026-w2-g08 | B11: 2026 | C11: regularSeason | D11: 2 | E11: 46128 | F11: 0.85416667 | G11: Moorestown Upper Elementary | H11: trust-the-process | I11: department-of-offense | J11: 20 | K11: 34 | L11: 36 | M11: 35 | N11: 56 | O11: 69 | P11: 0 | Q11: final | R11: normal | S11: Department Of Offense Erupts For 69 In High-Scoring Win Over Trust The Process | T11: Department of Offense jumped out to a 14-point halftime lead and never looked back in a 69-56 victory over Trust The Process. Even after TTP mounted a stronger second half, D.O.O. continued to answer offensively to secure the win.
A12: =B12&"-w"&D12&"-g"&TEXT(COUNTIFS($B$2:B12,B12,$D$2:D12,D12),"00") -> 2026-w3-g01 | B12: 2026 | C12: regularSeason | D12: 3 | E12: 46132 | F12: 0.77083333 | G12: Moorestown Upper Elementary | H12: hash-slinging-slashers | I12: free-agent-team | J12: 29 | K12: 10 | L12: 32 | M12: 22 | N12: 61 | O12: 32 | P12: 0 | Q12: final | R12: normal | S12: Hash-Slinging Slashers Continue Defensive Tear In Blowout Win | T12: Hash-Slinging Slashers suffocated the Free Agent Team defensively from start to finish, cruising to a 61-32 victory. The Slashers built a 19-point halftime lead and never allowed the Free Agents back into the game.
A13: =B13&"-w"&D13&"-g"&TEXT(COUNTIFS($B$2:B13,B13,$D$2:D13,D13),"00") -> 2026-w3-g02 | B13: 2026 | C13: regularSeason | D13: 3 | E13: 46132 | F13: 0.8125 | G13: Moorestown Upper Elementary | H13: prestige-worldwide | I13: trust-the-process | J13: 19 | K13: 23 | L13: 23 | M13: 37 | N13: 42 | O13: 60 | P13: 0 | Q13: final | R13: normal | S13: Trust The Process Pull Away Late To Stay Hot | T13: Trust The Process used a huge second half to break open a close game and defeat Prestige Worldwide 60-42. After leading by just four at halftime, TTP outscored Prestige 37-23 after the break behind a dominant second-half performance from Hakim Jackson, who scored 13 of his 17 points after halftime.
A14: =B14&"-w"&D14&"-g"&TEXT(COUNTIFS($B$2:B14,B14,$D$2:D14,D14),"00") -> 2026-w3-g03 | B14: 2026 | C14: regularSeason | D14: 3 | E14: 46134 | F14: 0.77083333 | G14: Moorestown Upper Elementary | H14: lmba-jam | I14: department-of-offense | N14: 65 | O14: 55 | P14: 0 | Q14: final | R14: normal | S14: LMBA Jam Outlast Department Of Offense In Offensive Showcase | T14: LMBA Jam continued its offensive resurgence with a 65-55 win over Department of Offense. LMBA Jam controlled the pace throughout the night and held off multiple D.O.O. runs to close out the 10-point victory.
A15: =B15&"-w"&D15&"-g"&TEXT(COUNTIFS($B$2:B15,B15,$D$2:D15,D15),"00") -> 2026-w3-g04 | B15: 2026 | C15: regularSeason | D15: 3 | E15: 46134 | F15: 0.8125 | G15: Moorestown Upper Elementary | H15: free-agent-team | I15: ball-starz | N15: 41 | O15: 90 | P15: 0 | Q15: final | R15: normal | S15: Ball Starz Turn Wednesday Night Into A Track Meet In 90-41 Rout | T15: Ball Starz delivered the most explosive offensive performance of the season, overwhelming the Free Agent Team 90-41. The Ball Starz pushed the tempo from the opening tip and never let up, turning the matchup into a full-court track meet while doubling up Free Agent Team on the scoreboard.
A16: =B16&"-w"&D16&"-g"&TEXT(COUNTIFS($B$2:B16,B16,$D$2:D16,D16),"00") -> 2026-w3-g05 | B16: 2026 | C16: regularSeason | D16: 3 | E16: 46134 | F16: 0.85416667 | G16: Moorestown Upper Elementary | H16: trust-the-process | I16: thrillers | N16: 64 | O16: 48 | P16: 0 | Q16: final | R16: normal | S16: Trust The Process Lock Down Thrillers In Statement Victory | T16: Trust The Process continued its strong midseason run with a convincing 64-48 win over Thrillers. TTP controlled both ends of the floor throughout the game and never allowed Thrillers to build consistent momentum.
A17: =B17&"-w"&D17&"-g"&TEXT(COUNTIFS($B$2:B17,B17,$D$2:D17,D17),"00") -> 2026-w3-g06 | B17: 2026 | C17: regularSeason | D17: 3 | E17: 46135 | F17: 0.8125 | G17: Moorestown Upper Elementary | H17: thrillers | I17: lmba-jam | J17: 15 | K17: 34 | L17: 13 | M17: 32 | N17: 28 | O17: 66 | P17: 0 | Q17: final | R17: normal | S17: LMBA Jam Steamroll Thrillers Behind Massive First Half | T17: LMBA Jam buried Thrillers early and never looked back in a dominant 66-28 victory. LMBA Jam raced out to a 34-15 halftime lead before completely shutting the door with another huge second half behind Anthony Shelepets, who poured in 26 points in the win.
A18: =B18&"-w"&D18&"-g"&TEXT(COUNTIFS($B$2:B18,B18,$D$2:D18,D18),"00") -> 2026-w3-g07 | B18: 2026 | C18: regularSeason | D18: 3 | E18: 46135 | F18: 0.85416667 | G18: Moorestown Upper Elementary | H18: hash-slinging-slashers | I18: prestige-worldwide | J18: 29 | K18: 20 | L18: 25 | M18: 25 | N18: 54 | O18: 45 | P18: 0 | Q18: final | R18: normal | S18: Hash-Slinging Slashers Stay Red Hot With Wire-To-Wire Win | T18: Hash-Slinging Slashers continued their impressive run with a 54-45 victory over Prestige Worldwide. The Slashers led by nine at halftime and matched Prestige basket-for-basket in the second half to finish off the win.
A19: =B19&"-w"&D19&"-g"&TEXT(COUNTIFS($B$2:B19,B19,$D$2:D19,D19),"00") -> 2026-w4-g01 | B19: 2026 | C19: regularSeason | D19: 4 | E19: 46140 | F19: 0.77083333 | G19: Moorestown Upper Elementary | H19: trust-the-process | I19: free-agent-team | N19: 83 | O19: 55 | P19: 0 | Q19: final | R19: normal | S19: Trust The Process Explodes For 83 In Blowout Victory | T19: Trust The Process explode offensively in an 83-55 rout of the Free Agent Team. TTP pushed the pace from the opening tip and never slowed down.
A20: =B20&"-w"&D20&"-g"&TEXT(COUNTIFS($B$2:B20,B20,$D$2:D20,D20),"00") -> 2026-w4-g02 | B20: 2026 | C20: regularSeason | D20: 4 | E20: 46140 | F20: 0.8125 | G20: Moorestown Upper Elementary | H20: department-of-offense | I20: prestige-worldwide | N20: 45 | O20: 48 | P20: 0 | Q20: final | R20: normal | S20: Prestige Worldwide Sneak Past Department Of Offense In Defensive Battle For First Win | T20: Prestige Worldwide survived a low-scoring thriller against Department of Offense, escaping with a 48-45 win for their first victory of the season. In his season debut, Travis Gibbs sparked Prestige with 15 points and five three-pointers, while timely defensive stops and clutch late possessions sealed the narrow win.
A21: =B21&"-w"&D21&"-g"&TEXT(COUNTIFS($B$2:B21,B21,$D$2:D21,D21),"00") -> 2026-w4-g03 | B21: 2026 | C21: regularSeason | D21: 4 | E21: 46140 | F21: 0.85416667 | G21: Moorestown Upper Elementary | H21: ball-starz | I21: hash-slinging-slashers | J21: 26 | K21: 15 | L21: 24 | M21: 10 | N21: 50 | O21: 25 | P21: 0 | Q21: final | R21: normal | S21: Ball Starz Defense Suffocates Slashers In 25-Point Blowout | T21: Ball Starz delivered a dominant two-way performance in a 50-25 dismantling of Hash-Slinging Slashers. After building an 11-point halftime advantage, the Ball Starz completely shut down the Slashers offense in the second half.
A22: =B22&"-w"&D22&"-g"&TEXT(COUNTIFS($B$2:B22,B22,$D$2:D22,D22),"00") -> 2026-w4-g04 | B22: 2026 | C22: regularSeason | D22: 4 | E22: 46141 | F22: 0.77083333 | G22: Moorestown Upper Elementary | H22: lmba-jam | I22: prestige-worldwide | J22: 32 | K22: 32 | L22: 27 | M22: 16 | N22: 59 | O22: 48 | P22: 0 | Q22: final | R22: normal | S22: LMBA Jam Pull Away Late After First-Half Shootout To Avoid Upset | T22: LMBA Jam broke open a tied game after halftime to defeat Prestige Worldwide 59-48. After both teams entered the break deadlocked at 32, LMBA Jam tightened up defensively and controlled the final stretch behind former MVP and future first-ballot Hall of Famer Dave Homsher, who erupted for 29 points and seven three-pointers in the win.
A23: =B23&"-w"&D23&"-g"&TEXT(COUNTIFS($B$2:B23,B23,$D$2:D23,D23),"00") -> 2026-w4-g05 | B23: 2026 | C23: regularSeason | D23: 4 | E23: 46141 | F23: 0.8125 | G23: Moorestown Upper Elementary | H23: hash-slinging-slashers | I23: trust-the-process | J23: 31 | K23: 26 | L23: 22 | M23: 27 | N23: 53 | O23: 62 | P23: 1 | Q23: final | R23: normal | S23: Trust The Process Survive Overtime Thriller Against Slashers | T23: Trust The Process erased a five-point halftime deficit and survived overtime to edge Hash-Slinging Slashers 62-53. TTP closed regulation strong before taking complete control in the extra period.
A24: =B24&"-w"&D24&"-g"&TEXT(COUNTIFS($B$2:B24,B24,$D$2:D24,D24),"00") -> 2026-w5-g01 | B24: 2026 | C24: regularSeason | D24: 5 | E24: 46146 | F24: 0.8125 | G24: Moorestown Upper Elementary | H24: free-agent-team | I24: ball-starz | J24: 19 | K24: 41 | L24: 17 | M24: 49 | N24: 36 | O24: 90 | P24: 0 | Q24: final | R24: normal | S24: Ball Starz Turn Blowout Win Over Free Agent Team Into 3-Point Contest | T24: Ball Starz caught fire from deep and never cooled off, burying 22 three-pointers in a 90-36 demolition of the Free Agent Team. The Ball Starz pushed the pace all night and turned the matchup into a full-court shooting exhibition from beyond the arc.
A25: =B25&"-w"&D25&"-g"&TEXT(COUNTIFS($B$2:B25,B25,$D$2:D25,D25),"00") -> 2026-w5-g02 | B25: 2026 | C25: regularSeason | D25: 5 | E25: 46146 | F25: 0.85416667 | G25: Moorestown Upper Elementary | H25: thrillers | I25: department-of-offense | J25: 23 | K25: 42 | L25: 29 | M25: 19 | N25: 52 | O25: 61 | P25: 0 | Q25: final | R25: normal | S25: Department Of Offense Hold Off Furious Thrillers Comeback | T25: Department of Offense looked headed for a blowout after building a 19-point halftime lead, but Thrillers mounted a huge second-half rally before ultimately falling 61-52. D.O.O. did just enough late to escape with the win led by Kyle Kelly and Chris Ellis who combined for 45 points in the victory.
A26: =B26&"-w"&D26&"-g"&TEXT(COUNTIFS($B$2:B26,B26,$D$2:D26,D26),"00") -> 2026-w5-g03 | B26: 2026 | C26: regularSeason | D26: 5 | E26: 46147 | F26: 0.77083333 | G26: Moorestown Upper Elementary | H26: ball-starz | I26: thrillers | J26: 34 | K26: 17 | L26: 24 | M26: 25 | N26: 58 | O26: 42 | P26: 0 | Q26: final | R26: normal | S26: Ball Starz Cruise Past Thrillers Behind Dominant First Half | T26: Ball Starz got their revenge from their early season loss to the Thrillers. Ball Starzjumped out early and never allowed Thrillers back into the game in a 58-42 victory. The Ball Starz carried a 17-point lead into halftime and controlled the tempo throughout the night.
A27: =B27&"-w"&D27&"-g"&TEXT(COUNTIFS($B$2:B27,B27,$D$2:D27,D27),"00") -> 2026-w5-g04 | B27: 2026 | C27: regularSeason | D27: 5 | E27: 46147 | F27: 0.8125 | G27: Moorestown Upper Elementary | H27: hash-slinging-slashers | I27: department-of-offense | N27: 20 | O27: 60 | P27: 0 | Q27: final | R27: forfeitHome | S27: Department Of Offense Awarded Forfeit Victory Over Slashers | T27: Department of Offense earned a 60-20 forfeit victory after Hash-Slinging Slashers were unable to field a valid lineup. The result keeps D.O.O. firmly in the playoff seeding mix heading into Week 6.
A28: =B28&"-w"&D28&"-g"&TEXT(COUNTIFS($B$2:B28,B28,$D$2:D28,D28),"00") -> 2026-w5-g05 | B28: 2026 | C28: regularSeason | D28: 5 | E28: 46147 | F28: 0.85416667 | G28: Moorestown Upper Elementary | H28: lmba-jam | I28: trust-the-process | J28: 31 | K28: 29 | L28: 41 | M28: 31 | N28: 72 | O28: 60 | P28: 0 | Q28: final | R28: normal | S28: LMBA Jam Win Offensive Shootout Against Trust The Process | T28: LMBA Jam outlasted Trust The Process in one of the season’s highest-scoring games, earning a 72-60 victory. LMBA Jam led by just two at halftime before pulling away behind a massive 41-point second half.
A29: =B29&"-w"&D29&"-g"&TEXT(COUNTIFS($B$2:B29,B29,$D$2:D29,D29),"00") -> 2026-w6-g01 | B29: 2026 | C29: regularSeason | D29: 6 | E29: 46153 | F29: 0.77083333 | G29: Moorestown Upper Elementary | H29: free-agent-team | I29: department-of-offense | J29: 15 | K29: 36 | L29: 5 | M29: 35 | N29: 20 | O29: 71 | P29: 0 | Q29: final | R29: normal | S29: Department Of Offense Deliver Week 6 Beatdown Of Free Agent Team | T29: Department of Offense overwhelmed the Free Agent Team from the opening tip in a lopsided 71-20 victory. D.O.O. built a 21-point halftime lead and completely shut the door by allowing just five second-half points.
A30: =B30&"-w"&D30&"-g"&TEXT(COUNTIFS($B$2:B30,B30,$D$2:D30,D30),"00") -> 2026-w6-g02 | B30: 2026 | C30: regularSeason | D30: 6 | E30: 46153 | F30: 0.8125 | G30: Moorestown Upper Elementary | H30: prestige-worldwide | I30: ball-starz | J30: 18 | K30: 46 | L30: 30 | M30: 30 | N30: 48 | O30: 76 | P30: 0 | Q30: final | R30: normal | S30: Thin Ball Starz Squad Handle Week 6 Challenge From Prestige Worldwide With Ease | T30: Ball Starz continued their dominant season with a convincing 76-48 win over Prestige Worldwide. MVP Front-Runner Guy Johnson was a surprise no-show come tip-off. Despite no bench, the Ball Starz built a 28-point halftime lead and cruised to another victory.
A31: =B31&"-w"&D31&"-g"&TEXT(COUNTIFS($B$2:B31,B31,$D$2:D31,D31),"00") -> 2026-w6-g03 | B31: 2026 | C31: regularSeason | D31: 6 | E31: 46154 | F31: 0.77083333 | G31: Moorestown Upper Elementary | H31: lmba-jam | I31: hash-slinging-slashers | J31: 27 | K31: 30 | L31: 40 | M31: 34 | N31: 67 | O31: 64 | P31: 0 | Q31: final | R31: normal | S31: Clemente Ignites LMBA Jam Second-Half Surge In Win Over Hash-Slinging Slashers. | T31: LMBA Jam exploded for 40 second-half points to erase a halftime deficit and defeat Hash-Slinging Slashers 67-64 in a Week 6 thriller. Chris Clemente buried four second-half threes while Jam sealed the win at the line, finishing a perfect 7-for-7 on clutch free throws down the stretch.
A32: =B32&"-w"&D32&"-g"&TEXT(COUNTIFS($B$2:B32,B32,$D$2:D32,D32),"00") -> 2026-w6-g04 | B32: 2026 | C32: regularSeason | D32: 6 | E32: 46154 | F32: 0.8125 | G32: Moorestown Upper Elementary | H32: thrillers | I32: trust-the-process | N32: 50 | O32: 82 | P32: 0 | Q32: final | R32: normal | S32: Trust The Process Explode For 82 In Offensive Clinic Against Thrillers | T32: Trust The Process turned in one of the league’s most complete offensive performances of the season, rolling past Thrillers 82-50 in Week 6. TTP buried 13 three-pointers and featured a balanced scoring attack led by Kevin Tierney’s 18 points and Jordan Wilcox’s 17, while Doug Adams kept Thrillers competitive early with a game-high 27 points and five triples.
A33: =B33&"-w"&D33&"-g"&TEXT(COUNTIFS($B$2:B33,B33,$D$2:D33,D33),"00") -> 2026-w6-g05 | B33: 2026 | C33: regularSeason | D33: 6 | E33: 46154 | F33: 0.85416667 | G33: Moorestown Upper Elementary | H33: prestige-worldwide | I33: free-agent-team | N33: 60 | O33: 20 | P33: 0 | Q33: final | R33: forfeitAway | S33: Prestige Worldwide Awarded Forfeit Victory Over Free Agents | T33: Prestige Worldwide earned a 60-20 forfeit victory after Free Agents were unable to field a valid lineup. The result gives Prestige Worldwide their second win of the season to vie for better playoff seeding ahead of Week 7.
A34: =B34&"-w"&D34&"-g"&TEXT(COUNTIFS($B$2:B34,B34,$D$2:D34,D34),"00") -> 2026-w6-g06 | B34: 2026 | C34: regularSeason | D34: 6 | E34: 46156 | F34: 0.8125 | G34: Moorestown Upper Elementary | H34: ball-starz | I34: trust-the-process | J34: 29 | K34: 41 | L34: 41 | M34: 27 | N34: 70 | O34: 68 | P34: 0 | Q34: final | R34: normal | S34: INSTANT CLASSIC! Ball Starz Close On 35-10 Run To Erase 23-Point Second-Half Deficit | T34: In one of the wildest games in recent history, Ball Starz stormed back from a 58-35 second-half deficit with under 12 minutes remaining to stun Trust The Process 70-68. Guy Johnson drilled a game-tying three with 13 seconds left before a costly TTP backcourt violation gave Ball Starz one final chance. Moments later, Ryan Fontanazza was fouled on a three-point attempt with 3.5 seconds remaining and calmly knocked down two clutch free throws to complete the comeback. Trust The Process repeatedly missed critical one-and-one FT opportunities down the stretch, opening the door for the furious 35-10 Ball Starz finish, while Jeff Savage’s half-court buzzer heave nearly stole the game back at the horn.
A35: =B35&"-w"&D35&"-g"&TEXT(COUNTIFS($B$2:B35,B35,$D$2:D35,D35),"00") -> 2026-w6-g07 | B35: 2026 | C35: regularSeason | D35: 6 | E35: 46156 | F35: 0.85416667 | G35: Moorestown Upper Elementary | H35: hash-slinging-slashers | I35: thrillers | J35: 19 | K35: 24 | L35: 24 | M35: 25 | N35: 43 | O35: 49 | P35: 0 | Q35: final | R35: normal
A36: =B36&"-w"&D36&"-g"&TEXT(COUNTIFS($B$2:B36,B36,$D$2:D36,D36),"00") -> 2026-w7-g01 | B36: 2026 | C36: regularSeason | D36: 7 | E36: 46160 | F36: 0.77083333 | G36: Moorestown Upper Elementary | H36: prestige-worldwide | I36: thrillers | J36: 46 | K36: 29 | L36: 14 | M36: 16 | N36: 60 | O36: 45 | P36: 0 | Q36: final | R36: normal
A37: =B37&"-w"&D37&"-g"&TEXT(COUNTIFS($B$2:B37,B37,$D$2:D37,D37),"00") -> 2026-w7-g02 | B37: 2026 | C37: regularSeason | D37: 7 | E37: 46160 | F37: 0.8125 | G37: Moorestown Upper Elementary | H37: trust-the-process | I37: free-agent-team | N37: 60 | O37: 20 | P37: 0 | Q37: final | R37: forfeitAway
A38: =B38&"-w"&D38&"-g"&TEXT(COUNTIFS($B$2:B38,B38,$D$2:D38,D38),"00") -> 2026-w7-g03 | B38: 2026 | C38: regularSeason | D38: 7 | E38: 46160 | F38: 0.85416667 | G38: Moorestown Upper Elementary | H38: lmba-jam | I38: department-of-offense | J38: 31 | K38: 26 | L38: 33 | M38: 34 | N38: 64 | O38: 60 | P38: 0 | Q38: final | R38: normal
A39: =B39&"-w"&D39&"-g"&TEXT(COUNTIFS($B$2:B39,B39,$D$2:D39,D39),"00") -> 2026-w7-g04 | B39: 2026 | C39: regularSeason | D39: 7 | E39: 46161 | F39: 0.77083333 | G39: Moorestown Upper Elementary | H39: department-of-offense | I39: prestige-worldwide | J39: 27 | K39: 24 | L39: 33 | M39: 25 | N39: 60 | O39: 49 | P39: 0 | Q39: final | R39: normal
A40: =B40&"-w"&D40&"-g"&TEXT(COUNTIFS($B$2:B40,B40,$D$2:D40,D40),"00") -> 2026-w7-g05 | B40: 2026 | C40: regularSeason | D40: 7 | E40: 46161 | F40: 0.8125 | G40: Moorestown Upper Elementary | H40: ball-starz | I40: lmba-jam | J40: 31 | K40: 26 | L40: 37 | M40: 9 | N40: 68 | O40: 35 | P40: 0 | Q40: final | R40: normal
...

Sheet playerGameStats
A1: gameId | B1: seasonId | C1: gameType | D1: week | E1: date | F1: time | G1: status | H1: resultType | I1: seasonTeamId | J1: teamId | K1: teamName | L1: opponentTeamId | M1: opponentTeamName | N1: playerId | O1: playerName | P1: jerseyNumber | Q1: points | R1: fgm | S1: threeFgm | T1: ftm | U1: fta
A2: 2026-w1-g01 | B2: 2026 | C2: regularSeason | D2: 1 | E2: 46112 | F2: 0.77083333 | G2: final | H2: normal | I2: 2026-ball-starz | J2: ball-starz | K2: Ball Starz | L2: lmba-jam | M2: LMBA Jam | N2: dom-sepko | O2: =_xlfn.XLOOKUP(N2,players!A:A,players!D:D,"") -> Dom Sepko | P2: {=_xlfn.XLOOKUP(I2&N2,rosterSpots!B:B&rosterSpots!D:D,rosterSpots!E:E,"")} -> 3 | Q2: =(playerGameStats!$R2 * 2) + (playerGameStats!$S2 * 3) + (playerGameStats!$T2) -> 4 | R2: 2 | S2: 0 | T2: 0 | U2: 0
A3: 2026-w1-g01 | B3: 2026 | C3: regularSeason | D3: 1 | E3: 46112 | F3: 0.77083333 | G3: final | H3: normal | I3: 2026-ball-starz | J3: ball-starz | K3: Ball Starz | L3: lmba-jam | M3: LMBA Jam | N3: ryan-maloney | O3: =_xlfn.XLOOKUP(N3,players!A:A,players!D:D,"") -> Ryan Maloney | P3: {=_xlfn.XLOOKUP(I3&N3,rosterSpots!B:B&rosterSpots!D:D,rosterSpots!E:E,"")} -> 5 | Q3: =(playerGameStats!$R3 * 2) + (playerGameStats!$S3 * 3) + (playerGameStats!$T3) -> 9 | R3: 0 | S3: 3 | T3: 0 | U3: 0
A4: 2026-w1-g01 | B4: 2026 | C4: regularSeason | D4: 1 | E4: 46112 | F4: 0.77083333 | G4: final | H4: normal | I4: 2026-ball-starz | J4: ball-starz | K4: Ball Starz | L4: lmba-jam | M4: LMBA Jam | N4: guy-johnson | O4: =_xlfn.XLOOKUP(N4,players!A:A,players!D:D,"") -> Guy Johnson | P4: {=_xlfn.XLOOKUP(I4&N4,rosterSpots!B:B&rosterSpots!D:D,rosterSpots!E:E,"")} -> 9 | Q4: =(playerGameStats!$R4 * 2) + (playerGameStats!$S4 * 3) + (playerGameStats!$T4) -> 23 | R4: 2 | S4: 6 | T4: 1 | U4: 1
A5: 2026-w1-g01 | B5: 2026 | C5: regularSeason | D5: 1 | E5: 46112 | F5: 0.77083333 | G5: final | H5: normal | I5: 2026-ball-starz | J5: ball-starz | K5: Ball Starz | L5: lmba-jam | M5: LMBA Jam | N5: matt-morini | O5: =_xlfn.XLOOKUP(N5,players!A:A,players!D:D,"") -> Matt Morini | P5: {=_xlfn.XLOOKUP(I5&N5,rosterSpots!B:B&rosterSpots!D:D,rosterSpots!E:E,"")} -> 11 | Q5: =(playerGameStats!$R5 * 2) + (playerGameStats!$S5 * 3) + (playerGameStats!$T5) -> 2 | R5: 1 | S5: 0 | T5: 0 | U5: 0
A6: 2026-w1-g01 | B6: 2026 | C6: regularSeason | D6: 1 | E6: 46112 | F6: 0.77083333 | G6: final | H6: normal | I6: 2026-ball-starz | J6: ball-starz | K6: Ball Starz | L6: lmba-jam | M6: LMBA Jam | N6: clayton-kunzweiler | O6: =_xlfn.XLOOKUP(N6,players!A:A,players!D:D,"") -> Clayton Kunzweiler | P6: {=_xlfn.XLOOKUP(I6&N6,rosterSpots!B:B&rosterSpots!D:D,rosterSpots!E:E,"")} -> 13 | Q6: =(playerGameStats!$R6 * 2) + (playerGameStats!$S6 * 3) + (playerGameStats!$T6) -> 12 | R6: 4 | S6: 1 | T6: 1 | U6: 1
A7: 2026-w1-g01 | B7: 2026 | C7: regularSeason | D7: 1 | E7: 46112 | F7: 0.77083333 | G7: final | H7: normal | I7: 2026-ball-starz | J7: ball-starz | K7: Ball Starz | L7: lmba-jam | M7: LMBA Jam | N7: ryan-chapman | O7: =_xlfn.XLOOKUP(N7,players!A:A,players!D:D,"") -> Ryan Chapman | P7: {=_xlfn.XLOOKUP(I7&N7,rosterSpots!B:B&rosterSpots!D:D,rosterSpots!E:E,"")} -> 20 | Q7: =(playerGameStats!$R7 * 2) + (playerGameStats!$S7 * 3) + (playerGameStats!$T7) -> 2 | R7: 1 | S7: 0 | T7: 0 | U7: 0
A8: 2026-w1-g01 | B8: 2026 | C8: regularSeason | D8: 1 | E8: 46112 | F8: 0.77083333 | G8: final | H8: normal | I8: 2026-ball-starz | J8: ball-starz | K8: Ball Starz | L8: lmba-jam | M8: LMBA Jam | N8: ryan-fontanazza | O8: =_xlfn.XLOOKUP(N8,players!A:A,players!D:D,"") -> Ryan Fontanazza | P8: {=_xlfn.XLOOKUP(I8&N8,rosterSpots!B:B&rosterSpots!D:D,rosterSpots!E:E,"")} -> 22 | Q8: =(playerGameStats!$R8 * 2) + (playerGameStats!$S8 * 3) + (playerGameStats!$T8) -> 4 | R8: 1 | S8: 0 | T8: 2 | U8: 3
A9: 2026-w1-g01 | B9: 2026 | C9: regularSeason | D9: 1 | E9: 46112 | F9: 0.77083333 | G9: final | H9: normal | I9: 2026-ball-starz | J9: ball-starz | K9: Ball Starz | L9: lmba-jam | M9: LMBA Jam | N9: sean-denson | O9: =_xlfn.XLOOKUP(N9,players!A:A,players!D:D,"") -> Sean Denson | P9: {=_xlfn.XLOOKUP(I9&N9,rosterSpots!B:B&rosterSpots!D:D,rosterSpots!E:E,"")} -> 33 | Q9: =(playerGameStats!$R9 * 2) + (playerGameStats!$S9 * 3) + (playerGameStats!$T9) -> 5 | R9: 1 | S9: 1 | T9: 0 | U9: 0
A10: 2026-w1-g01 | B10: 2026 | C10: regularSeason | D10: 1 | E10: 46112 | F10: 0.77083333 | G10: final | H10: normal | I10: 2026-lmba-jam | J10: lmba-jam | K10: LMBA Jam | L10: ball-starz | M10: Ball Starz | N10: dave-homsher | O10: =_xlfn.XLOOKUP(N10,players!A:A,players!D:D,"") -> Dave Homsher | P10: {=_xlfn.XLOOKUP(I10&N10,rosterSpots!B:B&rosterSpots!D:D,rosterSpots!E:E,"")} -> 3 | Q10: =(playerGameStats!$R10 * 2) + (playerGameStats!$S10 * 3) + (playerGameStats!$T10) -> 9 | R10: 3 | S10: 1 | T10: 0 | U10: 0
A11: 2026-w1-g01 | B11: 2026 | C11: regularSeason | D11: 1 | E11: 46112 | F11: 0.77083333 | G11: final | H11: normal | I11: 2026-lmba-jam | J11: lmba-jam | K11: LMBA Jam | L11: ball-starz | M11: Ball Starz | N11: angel-carrion | O11: =_xlfn.XLOOKUP(N11,players!A:A,players!D:D,"") -> Angel Carrion | P11: {=_xlfn.XLOOKUP(I11&N11,rosterSpots!B:B&rosterSpots!D:D,rosterSpots!E:E,"")} -> 7 | Q11: =(playerGameStats!$R11 * 2) + (playerGameStats!$S11 * 3) + (playerGameStats!$T11) -> 3 | R11: 1 | S11: 0 | T11: 1 | U11: 2
A12: 2026-w1-g01 | B12: 2026 | C12: regularSeason | D12: 1 | E12: 46112 | F12: 0.77083333 | G12: final | H12: normal | I12: 2026-lmba-jam | J12: lmba-jam | K12: LMBA Jam | L12: ball-starz | M12: Ball Starz | N12: dylan-meyler | O12: =_xlfn.XLOOKUP(N12,players!A:A,players!D:D,"") -> Dylan Meyler | P12: {=_xlfn.XLOOKUP(I12&N12,rosterSpots!B:B&rosterSpots!D:D,rosterSpots!E:E,"")} -> 10 | Q12: =(playerGameStats!$R12 * 2) + (playerGameStats!$S12 * 3) + (playerGameStats!$T12) -> 0 | R12: 0 | S12: 0 | T12: 0 | U12: 0
A13: 2026-w1-g01 | B13: 2026 | C13: regularSeason | D13: 1 | E13: 46112 | F13: 0.77083333 | G13: final | H13: normal | I13: 2026-lmba-jam | J13: lmba-jam | K13: LMBA Jam | L13: ball-starz | M13: Ball Starz | N13: brendan-scott | O13: =_xlfn.XLOOKUP(N13,players!A:A,players!D:D,"") -> Brendan Scott | P13: {=_xlfn.XLOOKUP(I13&N13,rosterSpots!B:B&rosterSpots!D:D,rosterSpots!E:E,"")} -> 11 | Q13: =(playerGameStats!$R13 * 2) + (playerGameStats!$S13 * 3) + (playerGameStats!$T13) -> 3 | R13: 1 | S13: 0 | T13: 1 | U13: 2
... A506: 2026-w7-g06 | B506: 2026 | C506: regularSeason | D506: 7 | E506: 46161 | F506: 0.85416667 | G506: final | H506: normal | I506: 2026-hash-slinging-slashers | J506: hash-slinging-slashers | K506: Hash-Slinging Slashers | L506: free-agent-team | M506: Free Agent Team | N506: ian-mccaw | O506: =_xlfn.XLOOKUP(N506,players!A:A,players!D:D,"") -> Ian McCaw | P506: {=_xlfn.XLOOKUP(I506&N506,rosterSpots!B:B&rosterSpots!D:D,rosterSpots!E:E,"")} -> 50 | Q506: =(playerGameStats!$R506 * 2) + (playerGameStats!$S506 * 3) + (playerGameStats!$T506) -> 10 | R506: 4 | S506: 0 | T506: 2 | U506: 2
A507: 2026-p-qf-g02 | B507: 2026 | C507: playoffs | D507: 8 | E507: 46175 | F507: 0.85416667 | G507: final | H507: normal | I507: 2026-lmba-jam | J507: lmba-jam | K507: LMBA Jam | L507: 2026-thrillers | M507: thrillers | N507: Thrillers | O507: Patrick Bellino | P507: 1 | Q507: =(playerGameStats!$R507 * 2) + (playerGameStats!$S507 * 3) + (playerGameStats!$T507) -> 0 | R507: 0 | S507: 0 | T507: 0 | U507: 0
A508: 2026-p-qf-g02 | B508: 2026 | C508: playoffs | D508: 8 | E508: 46175 | F508: 0.85416667 | G508: final | H508: normal | I508: 2026-lmba-jam | J508: lmba-jam | K508: LMBA Jam | L508: 2026-thrillers | M508: thrillers | N508: Thrillers | O508: Mike Ziller | P508: 2 | Q508: =(playerGameStats!$R508 * 2) + (playerGameStats!$S508 * 3) + (playerGameStats!$T508) -> 9 | R508: 2 | S508: 1 | T508: 2 | U508: 2
A509: 2026-p-qf-g02 | B509: 2026 | C509: playoffs | D509: 8 | E509: 46175 | F509: 0.85416667 | G509: final | H509: normal | I509: 2026-lmba-jam | J509: lmba-jam | K509: LMBA Jam | L509: 2026-thrillers | M509: thrillers | N509: Thrillers | O509: Dave Homsher | P509: 3 | Q509: =(playerGameStats!$R509 * 2) + (playerGameStats!$S509 * 3) + (playerGameStats!$T509) -> 8 | R509: 0 | S509: 2 | T509: 2 | U509: 2
A510: 2026-p-qf-g02 | B510: 2026 | C510: playoffs | D510: 8 | E510: 46175 | F510: 0.85416667 | G510: final | H510: normal | I510: 2026-lmba-jam | J510: lmba-jam | K510: LMBA Jam | L510: 2026-thrillers | M510: thrillers | N510: Thrillers | O510: Angel Carrion | P510: 7 | Q510: =(playerGameStats!$R510 * 2) + (playerGameStats!$S510 * 3) + (playerGameStats!$T510) -> 3 | R510: 0 | S510: 1 | T510: 0 | U510: 0
A511: 2026-p-qf-g02 | B511: 2026 | C511: playoffs | D511: 8 | E511: 46175 | F511: 0.85416667 | G511: final | H511: normal | I511: 2026-lmba-jam | J511: lmba-jam | K511: LMBA Jam | L511: 2026-thrillers | M511: thrillers | N511: Thrillers | O511: Thomas Nasto | P511: 9 | Q511: =(playerGameStats!$R511 * 2) + (playerGameStats!$S511 * 3) + (playerGameStats!$T511) -> 3 | R511: 1 | S511: 0 | T511: 1 | U511: 2
A512: 2026-p-qf-g02 | B512: 2026 | C512: playoffs | D512: 8 | E512: 46175 | F512: 0.85416667 | G512: final | H512: normal | I512: 2026-lmba-jam | J512: lmba-jam | K512: LMBA Jam | L512: 2026-thrillers | M512: thrillers | N512: Thrillers | O512: Scott Brusseler | P512: 14 | Q512: =(playerGameStats!$R512 * 2) + (playerGameStats!$S512 * 3) + (playerGameStats!$T512) -> 10 | R512: 3 | S512: 0 | T512: 4 | U512: 7
A513: 2026-p-qf-g02 | B513: 2026 | C513: playoffs | D513: 8 | E513: 46175 | F513: 0.85416667 | G513: final | H513: normal | I513: 2026-lmba-jam | J513: lmba-jam | K513: LMBA Jam | L513: 2026-thrillers | M513: thrillers | N513: Thrillers | O513: Gates Brooks | P513: 43 | Q513: =(playerGameStats!$R513 * 2) + (playerGameStats!$S513 * 3) + (playerGameStats!$T513) -> 0 | R513: 0 | S513: 0 | T513: 0 | U513: 0
A514: 2026-p-qf-g02 | B514: 2026 | C514: playoffs | D514: 8 | E514: 46175 | F514: 0.85416667 | G514: final | H514: normal | I514: 2026-lmba-jam | J514: lmba-jam | K514: LMBA Jam | L514: 2026-thrillers | M514: thrillers | N514: Thrillers | O514: Anthony Shelepets | P514: 53 | Q514: =(playerGameStats!$R514 * 2) + (playerGameStats!$S514 * 3) + (playerGameStats!$T514) -> 18 | R514: 9 | S514: 0 | T514: 0 | U514: 0
A515: 2026-p-qf-g02 | B515: 2026 | C515: playoffs | D515: 8 | E515: 46175 | F515: 0.85416667 | G515: final | H515: normal | I515: 2026-thrillers | J515: thrillers | K515: Thrillers | L515: 2026-lmba-jam | M515: lmba-jam | N515: LMBA Jam | O515: Manthan Tailor | P515: 2 | Q515: =(playerGameStats!$R515 * 2) + (playerGameStats!$S515 * 3) + (playerGameStats!$T515) -> 3 | R515: 0 | S515: 1 | T515: 0 | U515: 0
A516: 2026-p-qf-g02 | B516: 2026 | C516: playoffs | D516: 8 | E516: 46175 | F516: 0.85416667 | G516: final | H516: normal | I516: 2026-thrillers | J516: thrillers | K516: Thrillers | L516: 2026-lmba-jam | M516: lmba-jam | N516: LMBA Jam | O516: Doug Adams | P516: 3 | Q516: =(playerGameStats!$R516 * 2) + (playerGameStats!$S516 * 3) + (playerGameStats!$T516) -> 23 | R516: 4 | S516: 4 | T516: 3 | U516: 5
A517: 2026-p-qf-g02 | B517: 2026 | C517: playoffs | D517: 8 | E517: 46175 | F517: 0.85416667 | G517: final | H517: normal | I517: 2026-thrillers | J517: thrillers | K517: Thrillers | L517: 2026-lmba-jam | M517: lmba-jam | N517: LMBA Jam | O517: Janos Vajda | P517: 5 | Q517: =(playerGameStats!$R517 * 2) + (playerGameStats!$S517 * 3) + (playerGameStats!$T517) -> 6 | R517: 0 | S517: 2 | T517: 0 | U517: 0
A518: 2026-p-qf-g02 | B518: 2026 | C518: playoffs | D518: 8 | E518: 46175 | F518: 0.85416667 | G518: final | H518: normal | I518: 2026-thrillers | J518: thrillers | K518: Thrillers | L518: 2026-lmba-jam | M518: lmba-jam | N518: LMBA Jam | O518: Brett Ziller | P518: 8 | Q518: =(playerGameStats!$R518 * 2) + (playerGameStats!$S518 * 3) + (playerGameStats!$T518) -> 12 | R518: 3 | S518: 2 | T518: 0 | U518: 4
... A549: 2026-p-qf-g04 | B549: 2026 | C549: playoffs | D549: 8 | E549: 46176 | F549: 0.8125 | G549: final | H549: normal | I549: 2026-hash-slinging-slashers | J549: hash-slinging-slashers | K549: Hash-Slinging Slashers | L549: department-of-offense | M549: Department of Offense | N549: ian-mccaw | O549: Ian Mccaw | P549: 50 | Q549: =(playerGameStats!$R549 * 2) + (playerGameStats!$S549 * 3) + (playerGameStats!$T549) -> 9 | R549: 4 | S549: 0 | T549: 1 | U549: 2

Sheet weeklyAwards
A1: awardId | B1: seasonId | C1: week | D1: awardName | E1: recipientName | F1: playerId | G1: seasonTeamId | H1: title | I1: body
A2: =LOWER(B2&"-w"&C2&"-"&SUBSTITUTE(SUBSTITUTE(SUBSTITUTE(SUBSTITUTE(SUBSTITUTE(TRIM(D2)," ","-"),"'",""),":",""),".",""),",","")) -> 2026-w1-player-of-the-week | B2: 2026 | C2: 1 | D2: Player of the Week | E2: Guy Johnson | F2: guy-johnson | G2: 2026-ball-starz | H2: Still That Guy | I2: The reigning MVP opened 2026 right where he left off, dropping 23 points to lead Ball Starz past LMBA Jam in an opening-night championship rematch.
A3: =LOWER(B3&"-w"&C3&"-"&SUBSTITUTE(SUBSTITUTE(SUBSTITUTE(SUBSTITUTE(SUBSTITUTE(TRIM(D3)," ","-"),"'",""),":",""),".",""),",","")) -> 2026-w1-heat-check-award | B3: 2026 | C3: 1 | D3: Heat Check Award | E3: Doug Adams | F3: doug-adams | G3: 2026-thrillers | H3: Second-Half Flamethrower | I3: Doug Adams caught fire in the second half, pouring in 23 points to lead Thrillers back from a halftime deficit against Department of Offense on opening night.
A4: =LOWER(B4&"-w"&C4&"-"&SUBSTITUTE(SUBSTITUTE(SUBSTITUTE(SUBSTITUTE(SUBSTITUTE(TRIM(D4)," ","-"),"'",""),":",""),".",""),",","")) -> 2026-w2-player-of-the-week | B4: 2026 | C4: 2 | D4: Player of the Week | E4: Doug Adams | F4: doug-adams | G4: 2026-thrillers | H4: Captain Comeback | I4: Doug Adams delivered another huge performance for Thrillers in Week 2, pouring in 20 points with 12 coming in the second half to fuel yet another comeback victory — this time against previously powerhouse Ball Starz.
A5: =LOWER(B5&"-w"&C5&"-"&SUBSTITUTE(SUBSTITUTE(SUBSTITUTE(SUBSTITUTE(SUBSTITUTE(TRIM(D5)," ","-"),"'",""),":",""),".",""),",","")) -> 2026-w2-logo-lillard-buzzer-beater-award | B5: 2026 | C5: 2 | D5: Logo Lillard Buzzer-Beater Award | E5: Nkenna Opara | F5: nkenna-opara | G5: 2026-free-agent-team | H5: Dame Time In Moorestown | I5: With the clock winding down, NKenna Opara drilled a cold-blooded long-range step-back three at the buzzer to lift the Free Agent Team over Thrillers in one of the season’s earliest jaw-dropping moments.
A6: =LOWER(B6&"-w"&C6&"-"&SUBSTITUTE(SUBSTITUTE(SUBSTITUTE(SUBSTITUTE(SUBSTITUTE(TRIM(D6)," ","-"),"'",""),":",""),".",""),",","")) -> 2026-w2-built-different-award | B6: 2026 | C6: 2 | D6: Built Different Award | E6: LMBA Jam | G6: 2026-lmba-jam | H6: 70-Piece Combo Meal | I6: LMBA Jam dropped 70 points on the Free Agent Team in one of the league’s first true offensive explosions of the season.
A7: =LOWER(B7&"-w"&C7&"-"&SUBSTITUTE(SUBSTITUTE(SUBSTITUTE(SUBSTITUTE(SUBSTITUTE(TRIM(D7)," ","-"),"'",""),":",""),".",""),",","")) -> 2026-w2-x-factor-award | B7: 2026 | C7: 2 | D7: X-Factor Award | E7: Grant Clark | F7: grant-clark | G7: 2026-department-of-offense | H7: Glue Guy Energy | I7: Grant Clark delivered one of the most complete performances of Week 2 in Department of Offense’s win over Trust The Process, knocking down timely shots, spacing the floor, and providing steady two-way play finishing with 19 points in an early statement team victory.
A8: =LOWER(B8&"-w"&C8&"-"&SUBSTITUTE(SUBSTITUTE(SUBSTITUTE(SUBSTITUTE(SUBSTITUTE(TRIM(D8)," ","-"),"'",""),":",""),".",""),",","")) -> 2026-w3-player-of-the-week | B8: 2026 | C8: 3 | D8: Player of the Week | E8: Anthony Shelepets | F8: anthony-shelepets | G8: 2026-lmba-jam | H8: Certified Bucket | I8: Anthony Shelepets dominated Week 3 for LMBA Jam, highlighted by a week-high 26-point performance against Thrillers after already scoring 19 in a win earlier in the week versus Department of Offense.
A9: =LOWER(B9&"-w"&C9&"-"&SUBSTITUTE(SUBSTITUTE(SUBSTITUTE(SUBSTITUTE(SUBSTITUTE(TRIM(D9)," ","-"),"'",""),":",""),".",""),",","")) -> 2026-w3-sharpshooter-award | B9: 2026 | C9: 3 | D9: Sharpshooter Award | E9: Keshon Coleman | F9: keshon-coleman | G9: 2026-hash-slinging-slashers | H9: Microwave Minutes | I9: Keshon Coleman turned into a flamethrower against Prestige Worldwide, knocking down six triples and finishing with 18 points for the Slashers.
A10: =LOWER(B10&"-w"&C10&"-"&SUBSTITUTE(SUBSTITUTE(SUBSTITUTE(SUBSTITUTE(SUBSTITUTE(TRIM(D10)," ","-"),"'",""),":",""),".",""),",","")) -> 2026-w3-every-dawg-has-his-day-award | B10: 2026 | C10: 3 | D10: Every Dawg Has His Day Award | E10: Hakim Jackson | F10: hakim-jackson | G10: 2026-trust-the-process | H10: Career Night Energy | I10: Often overlooked behind the likes of Wilcox, Sweeney, and Tierney, Hakim Jackson is known more for doing the dirty work and embracing his role. In Week 3, though, he exploded for 17 points to help lead Trust The Process past Prestige Worldwide.
A11: =LOWER(B11&"-w"&C11&"-"&SUBSTITUTE(SUBSTITUTE(SUBSTITUTE(SUBSTITUTE(SUBSTITUTE(TRIM(D11)," ","-"),"'",""),":",""),".",""),",","")) -> 2026-w3-macgyver-award | B11: 2026 | C11: 3 | D11: MacGyver Award | E11: Week 3 Scorekeepers | H11: Loose Leaf Legends | I11: When the official scorebook disappeared before tip-off on 4/22, the Week 3 scorekeepers somehow kept the entire league running using notebook paper, tally marks, and pure LM determination and ingenuity.
A12: =LOWER(B12&"-w"&C12&"-"&SUBSTITUTE(SUBSTITUTE(SUBSTITUTE(SUBSTITUTE(SUBSTITUTE(TRIM(D12)," ","-"),"'",""),":",""),".",""),",","")) -> 2026-w4-player-of-the-week | B12: 2026 | C12: 4 | D12: Player of the Week | E12: Dave Homsher | F12: dave-homsher | G12: 2026-lmba-jam | H12: Vintage MVP | I12: Former MVP Dave Homsher delivered the biggest performance of Week 4, exploding for 29 points and seven three-pointers in LMBA Jam’s win over Prestige Worldwide.
A13: =LOWER(B13&"-w"&C13&"-"&SUBSTITUTE(SUBSTITUTE(SUBSTITUTE(SUBSTITUTE(SUBSTITUTE(TRIM(D13)," ","-"),"'",""),":",""),".",""),",","")) -> 2026-w4-trey-murphy-iii-most-3pm-in-a-loss-award | B13: 2026 | C13: 4 | D13: Trey Murphy III Most-3PM-in-a-Loss Award | E13: Kevin Carroll | F13: kevin-carroll | G13: 2026-prestige-worldwide | H13: One-Man Flamethrower | I13: Kevin Carroll could not miss against LMBA Jam, pouring in 25 points and draining seven triples in one of the league’s hottest shooting performances of the season. However, it wasn't enough for his squad to pull off the upset versus LMBA Jam.
A14: =LOWER(B14&"-w"&C14&"-"&SUBSTITUTE(SUBSTITUTE(SUBSTITUTE(SUBSTITUTE(SUBSTITUTE(TRIM(D14)," ","-"),"'",""),":",""),".",""),",","")) -> 2026-w4-somebody-guard-him-award | B14: 2026 | C14: 4 | D14: Somebody Guard Him Award | E14: Ben Golden | F14: ben-golden | G14: 2026-hash-slinging-slashers | H14: Refused To Let Them Die | I14: Ben Golden put together one of the grittiest performances of the season in Week 4, scoring 26 points — including 14 in the second half — to help Hash-Slinging Slashers storm back and force overtime against Trust The Process before ultimately falling short.
A15: =LOWER(B15&"-w"&C15&"-"&SUBSTITUTE(SUBSTITUTE(SUBSTITUTE(SUBSTITUTE(SUBSTITUTE(TRIM(D15)," ","-"),"'",""),":",""),".",""),",","")) -> 2026-w4-dawg-award | B15: 2026 | C15: 4 | D15: Dawg Award | E15: Jordan Wilcox | F15: jordan-wilcox | G15: 2026-trust-the-process | H15: Relentless Bucket Getter | I15: Jordan Wilcox stayed red hot in Week 4, averaging 22 points across two wins and continuing to anchor the Trust The Process offense.
A16: =LOWER(B16&"-w"&C16&"-"&SUBSTITUTE(SUBSTITUTE(SUBSTITUTE(SUBSTITUTE(SUBSTITUTE(TRIM(D16)," ","-"),"'",""),":",""),".",""),",","")) -> 2026-w5-player-of-the-week | B16: 2026 | C16: 5 | D16: Player of the Week | E16: Guy Johnson | F16: guy-johnson | G16: 2026-ball-starz | H16: Automatic From Deep | I16: Guy Johnson continued his MVP-caliber season in Week 5, scoring 42 total points across two Ball Starz wins while knocking down 12 three-pointers, including an eight-triple barrage against the Free Agent Team.
A17: =LOWER(B17&"-w"&C17&"-"&SUBSTITUTE(SUBSTITUTE(SUBSTITUTE(SUBSTITUTE(SUBSTITUTE(TRIM(D17)," ","-"),"'",""),":",""),".",""),",","")) -> 2026-w5-"i-circled-this-game-in-march"-award | B17: 2026 | C17: 5 | D17: "I Circled This Game In March" Award | E17: Kyle Kelly | F17: kyle-kelly | G17: 2026-department-of-offense | H17: Some Things Are Personal | I17: Facing his former team, Kyle Kelly delivered a statement performance for Department of Offense, scoring 23 points and knocking down five three-pointers against Thrillers in one of Week 5’s biggest revenge games.
A18: =LOWER(B18&"-w"&C18&"-"&SUBSTITUTE(SUBSTITUTE(SUBSTITUTE(SUBSTITUTE(SUBSTITUTE(TRIM(D18)," ","-"),"'",""),":",""),".",""),",","")) -> 2026-w5-open-gym-shootaround | B18: 2026 | C18: 5 | D18: Open Gym Shootaround | E18: Ball Starz | G18: 2026-ball-starz | H18: Wednesday Night LA Fitness Run | I18: Ball Starz turned their Week 5 matchup against the Free Agent Team into a full-on open gym shooting session, raining in 22 three-pointers and pushing the pace all night in a 90-point offensive explosion.
A19: =LOWER(B19&"-w"&C19&"-"&SUBSTITUTE(SUBSTITUTE(SUBSTITUTE(SUBSTITUTE(SUBSTITUTE(TRIM(D19)," ","-"),"'",""),":",""),".",""),",","")) -> 2026-w5-dawg-award | B19: 2026 | C19: 5 | D19: Dawg Award | E19: Scott Brusseler | F19: scott-brusseler | G19: 2026-lmba-jam | H19: Downhill All Night | I19: Scott Brusseler relentlessly attacked the rim in LMBA Jam’s win over Trust The Process, finishing with 18 points while going 8-for-10 from the free throw line.
A20: =LOWER(B20&"-w"&C20&"-"&SUBSTITUTE(SUBSTITUTE(SUBSTITUTE(SUBSTITUTE(SUBSTITUTE(TRIM(D20)," ","-"),"'",""),":",""),".",""),",","")) -> 2026-w5-waka-flaka-hard-in-the-paint-award | B20: 2026 | C20: 5 | D20: Waka Flaka Hard In The Paint Award | E20: Anthony Shelepets | F20: anthony-shelepets | G20: 2026-lmba-jam | H20: No Threes Needed | I20: In an era dominated by three-pointers, Anthony Shelepets casually dropped 20 points against Trust The Process without attempting a single triple.
A21: =LOWER(B21&"-w"&C21&"-"&SUBSTITUTE(SUBSTITUTE(SUBSTITUTE(SUBSTITUTE(SUBSTITUTE(TRIM(D21)," ","-"),"'",""),":",""),".",""),",","")) -> 2026-w6-big-baller-award | B21: 2026 | C21: 6 | D21: Big Baller Award | E21: Guy Johnson | F21: guy-johnson | G21: 2026-ball-starz | H21: New Whip. Same Big Shots. | I21: Guy Johnson missed Ball Starz’s Tuesday matchup against Prestige Worldwide after reportedly getting stuck at the dealership spending his MVP bonus money. He showed up Thursday in the new whip and immediately reminded the league who he is, burying a cold-blooded game-tying three with 13 seconds left to help fuel Ball Starz’s miraculous comeback win over Trust The Process.
A22: =LOWER(B22&"-w"&C22&"-"&SUBSTITUTE(SUBSTITUTE(SUBSTITUTE(SUBSTITUTE(SUBSTITUTE(TRIM(D22)," ","-"),"'",""),":",""),".",""),",","")) -> 2026-w6-larry-wright-win-it-at-the-line-award | B22: 2026 | C22: 6 | D22: Larry Wright Win-It-at-the-Line Award | E22: Ryan Fontanazza | F22: ryan-fontanazza | G22: 2026-ball-starz | H22: No Fear Free Throws | I22: Ryan Fontanazza stepped to the line with the game on the line and calmly knocked down the winning free throws with 3.5 seconds remaining to cap Ball Starz’s miracle comeback against Trust The Process.
A23: =LOWER(B23&"-w"&C23&"-"&SUBSTITUTE(SUBSTITUTE(SUBSTITUTE(SUBSTITUTE(SUBSTITUTE(TRIM(D23)," ","-"),"'",""),":",""),".",""),",","")) -> 2026-w6-sharpshooter-award | B23: 2026 | C23: 6 | D23: Sharpshooter Award | E23: Chris Clemente | F23: chris-clemente | G23: 2026-lmba-jam | H23: Second-Half Flamethrower | I23: Chris Clemente caught fire in the second half against Hash-Slinging Slashers, drilling four clutch three-pointers after halftime to help LMBA Jam pull away in a huge Week 6 victory.
A24: =LOWER(B24&"-w"&C24&"-"&SUBSTITUTE(SUBSTITUTE(SUBSTITUTE(SUBSTITUTE(SUBSTITUTE(TRIM(D24)," ","-"),"'",""),":",""),".",""),",","")) -> 2026-w6-no-supporting-cast-award | B24: 2026 | C24: 6 | D24: No Supporting Cast Award | E24: Doug Adams | F24: doug-adams | G24: 2026-thrillers | H24: Despite The Loss... | I24: Doug Adams did everything he could to keep Thrillers competitive against Trust The Process, exploding for 27 points and five threes while accounting for over half of the team’s offense in the loss.

Sheet seasonAwards
A1: seasonId | B1: awardName | C1: rank | D1: playerId | E1: seasonTeamId | F1: title | G1: body

Sheet README_playerGameStats
A1: playerGameStats Template Instructions
A2: 1. This sheet includes one row for every rostered player on both teams for each normal scheduled/final game.
A3: 2. Delete rows for players who did not play (DNP).
A4: 3. Keep rows for players who played but had no tracked stats, and enter 0 for points/fgm/threeFgm/ftm/fta.
A5: 4. For forfeits, cancelled, or postponed games, no rows were generated.
A6: 5. The app should treat remaining rows as Games Played entries.
A7: 6. Stat columns to fill: points, fgm, threeFgm, ftm, fta.

Sheet selection_values
A1: ball-starz | D1: scheduled | F1: 0.77083333 | H1: regularSeason | J1: normal
A2: lmba-jam | D2: final | F2: 0.8125 | H2: playoffs | J2: forfeitHome
A3: thrillers | D3: postponed | F3: 0.85416667 | H3: championship | J3: forfeitAway
A4: department-of-offense | D4: cancelled
A5: hash-slinging-slashers
A6: trust-the-process
A7: prestige-worldwide
A8: free-agent-team
